Workbook

Sheet Employee_Shifts
A1: Store Daily Targets | C1: Sunday | E1: Monday | G1: Tuesday | I1: Wednesday | K1: Thursday | M1: Friday | O1: Saturday | Q1: Weekly Total
A2: Daily Target → | C2: 3200 | E2: 4100 | G2: 3900 | I2: 4000 | K2: 4300 | M2: 6800 | O2: 7200 | Q2: =SUM(C2,E2,G2,I2,K2,M2,O2) -> 33500
R3: Working columns: person weight = shift value x role factor (nothing to edit here)
A4: Name | B4: Role | C4: Shift | D4: Target | E4: Shift | F4: Target | G4: Shift | H4: Target | I4: Shift | J4: Target | K4: Shift | L4: Target | M4: Shift | N4: Target | O4: Shift | P4: Target | Q4: Week Total | R4: Role factor | S4: Sun weight | T4: Mon weight | U4: Tue weight | V4: Wed weight | W4: Thu weight | X4: Fri weight | Y4: Sat weight
A5: Employee 01 | B5: Sales Assistant | D5: =IF(S5=0,0,S5/S$35*C$2) -> 0 | E5: 10:00-19:00 | F5: =IF(T5=0,0,T5/T$35*E$2) -> 705.16159 | H5: =IF(U5=0,0,U5/U$35*G$2) -> 0 | J5: =IF(V5=0,0,V5/V$35*I$2) -> 0 | K5: 12:30-19:00 | L5: =IF(W5=0,0,W5/W$35*K$2) -> 515.60206 | N5: =IF(X5=0,0,X5/X$35*M$2) -> 0 | O5: 8:00-17:00 | P5: =IF(Y5=0,0,Y5/Y$35*O$2) -> 719.39974 | Q5: =SUM(D5,F5,H5,J5,L5,N5,P5) -> 1940.1634 | R5: =IFERROR(INDEX(RoleFactor,MATCH(B5,RoleList,0)),1) -> 1 | S5: =IF(C5="",0,INDEX(SunValue,MATCH(C5,ShiftList,0))*$R5) -> 0 | T5: =IF(E5="",0,INDEX(MonValue,MATCH(E5,ShiftList,0))*$R5) -> 1.02 | U5: =IF(G5="",0,INDEX(TueValue,MATCH(G5,ShiftList,0))*$R5) -> 0 | V5: =IF(I5="",0,INDEX(WedValue,MATCH(I5,ShiftList,0))*$R5) -> 0 | W5: =IF(K5="",0,INDEX(ThuValue,MATCH(K5,ShiftList,0))*$R5) -> 0.79096154 | X5: =IF(M5="",0,INDEX(FriValue,MATCH(M5,ShiftList,0))*$R5) -> 0 | Y5: =IF(O5="",0,INDEX(SatValue,MATCH(O5,ShiftList,0))*$R5) -> 0.84
A6: Employee 02 | B6: Sales Assistant | D6: =IF(S6=0,0,S6/S$35*C$2) -> 0 | E6: 8:00-17:00 | F6: =IF(T6=0,0,T6/T$35*E$2) -> 540.77752 | G6: 11:30-20:30 | H6: =IF(U6=0,0,U6/U$35*G$2) -> 839.87166 | I6: 12:30-19:00 | J6: =IF(V6=0,0,V6/V$35*I$2) -> 540.61929 | K6: 10:00-17:00 | L6: =IF(W6=0,0,W6/W$35*K$2) -> 517.53617 | M6: 13:30-20:30 | N6: =IF(X6=0,0,X6/X$35*M$2) -> 987.26011 | O6: 13:30-20:30 | P6: =IF(Y6=0,0,Y6/Y$35*O$2) -> 606.87883 | Q6: =SUM(D6,F6,H6,J6,L6,N6,P6) -> 4032.9436 | R6: =IFERROR(INDEX(RoleFactor,MATCH(B6,RoleList,0)),1) -> 1 | S6: =IF(C6="",0,INDEX(SunValue,MATCH(C6,ShiftList,0))*$R6) -> 0 | T6: =IF(E6="",0,INDEX(MonValue,MATCH(E6,ShiftList,0))*$R6) -> 0.78222222 | U6: =IF(G6="",0,INDEX(TueValue,MATCH(G6,ShiftList,0))*$R6) -> 0.96888889 | V6: =IF(I6="",0,INDEX(WedValue,MATCH(I6,ShiftList,0))*$R6) -> 0.78980769 | W6: =IF(K6="",0,INDEX(ThuValue,MATCH(K6,ShiftList,0))*$R6) -> 0.79392857 | X6: =IF(M6="",0,INDEX(FriValue,MATCH(M6,ShiftList,0))*$R6) -> 0.79276786 | Y6: =IF(O6="",0,INDEX(SatValue,MATCH(O6,ShiftList,0))*$R6) -> 0.70861607
A7: Employee 03 | B7: Sales Assistant | C7: 10:00-14:30 | D7: =IF(S7=0,0,S7/S$35*C$2) -> 300.1751 | E7: 10:00-19:00 | F7: =IF(T7=0,0,T7/T$35*E$2) -> 705.16159 | G7: 10:00-14:30 | H7: =IF(U7=0,0,U7/U$35*G$2) -> 454.12785 | J7: =IF(V7=0,0,V7/V$35*I$2) -> 0 | K7: 10:00-14:30 | L7: =IF(W7=0,0,W7/W$35*K$2) -> 325.93371 | M7: 12:30-19:00 | N7: =IF(X7=0,0,X7/X$35*M$2) -> 985.01064 | O7: 8:00-17:00 | P7: =IF(Y7=0,0,Y7/Y$35*O$2) -> 719.39974 | Q7: =SUM(D7,F7,H7,J7,L7,N7,P7) -> 3489.8086 | R7: =IFERROR(INDEX(RoleFactor,MATCH(B7,RoleList,0)),1) -> 1 | S7: =IF(C7="",0,INDEX(SunValue,MATCH(C7,ShiftList,0))*$R7) -> 0.33333333 | T7: =IF(E7="",0,INDEX(MonValue,MATCH(E7,ShiftList,0))*$R7) -> 1.02 | U7: =IF(G7="",0,INDEX(TueValue,MATCH(G7,ShiftList,0))*$R7) -> 0.52388889 | V7: =IF(I7="",0,INDEX(WedValue,MATCH(I7,ShiftList,0))*$R7) -> 0 | W7: =IF(K7="",0,INDEX(ThuValue,MATCH(K7,ShiftList,0))*$R7) -> 0.5 | X7: =IF(M7="",0,INDEX(FriValue,MATCH(M7,ShiftList,0))*$R7) -> 0.79096154 | Y7: =IF(O7="",0,INDEX(SatValue,MATCH(O7,ShiftList,0))*$R7) -> 0.84
A8: Employee 04 | B8: Senior Manager | C8: 10:00-17:00 | D8: =IF(S8=0,0,S8/S$35*C$2) -> 444.8595 | F8: =IF(T8=0,0,T8/T$35*E$2) -> 0 | G8: 11:30-20:30 | H8: =IF(U8=0,0,U8/U$35*G$2) -> 671.89732 | I8: 13:30-20:30 | J8: =IF(V8=0,0,V8/V$35*I$2) -> 410.59912 | K8: 10:00-19:00 | L8: =IF(W8=0,0,W8/W$35*K$2) -> 527.28831 | M8: 8:00-17:00 | N8: =IF(X8=0,0,X8/X$35*M$2) -> 722.84672 | O8: 13:30-20:30 | P8: =IF(Y8=0,0,Y8/Y$35*O$2) -> 485.50306 | Q8: =SUM(D8,F8,H8,J8,L8,N8,P8) -> 3262.994 | R8: =IFERROR(INDEX(RoleFactor,MATCH(B8,RoleList,0)),1) -> 0.8 | S8: =IF(C8="",0,INDEX(SunValue,MATCH(C8,ShiftList,0))*$R8) -> 0.494 | T8: =IF(E8="",0,INDEX(MonValue,MATCH(E8,ShiftList,0))*$R8) -> 0 | U8: =IF(G8="",0,INDEX(TueValue,MATCH(G8,ShiftList,0))*$R8) -> 0.77511111 | V8: =IF(I8="",0,INDEX(WedValue,MATCH(I8,ShiftList,0))*$R8) -> 0.59985714 | W8: =IF(K8="",0,INDEX(ThuValue,MATCH(K8,ShiftList,0))*$R8) -> 0.80888889 | X8: =IF(M8="",0,INDEX(FriValue,MATCH(M8,ShiftList,0))*$R8) -> 0.58044444 | Y8: =IF(O8="",0,INDEX(SatValue,MATCH(O8,ShiftList,0))*$R8) -> 0.56689286
A9: Employee 05 | B9: Sales Assistant | C9: 13:30-20:30 | D9: =IF(S9=0,0,S9/S$35*C$2) -> 432.21195 | E9: 8:00-17:00 | F9: =IF(T9=0,0,T9/T$35*E$2) -> 540.77752 | G9: 10:00-17:00 | H9: =IF(U9=0,0,U9/U$35*G$2) -> 708.33212 | I9: 10:00-14:30 | J9: =IF(V9=0,0,V9/V$35*I$2) -> 358.59924 | L9: =IF(W9=0,0,W9/W$35*K$2) -> 0 | M9: 11:30-20:30 | N9: =IF(X9=0,0,X9/X$35*M$2) -> 1221.1184 | O9: 11:30-20:30 | P9: =IF(Y9=0,0,Y9/Y$35*O$2) -> 800.76042 | Q9: =SUM(D9,F9,H9,J9,L9,N9,P9) -> 4061.7996 | R9: =IFERROR(INDEX(RoleFactor,MATCH(B9,RoleList,0)),1) -> 1 | S9: =IF(C9="",0,INDEX(SunValue,MATCH(C9,ShiftList,0))*$R9) -> 0.47995536 | T9: =IF(E9="",0,INDEX(MonValue,MATCH(E9,ShiftList,0))*$R9) -> 0.78222222 | U9: =IF(G9="",0,INDEX(TueValue,MATCH(G9,ShiftList,0))*$R9) -> 0.81714286 | V9: =IF(I9="",0,INDEX(WedValue,MATCH(I9,ShiftList,0))*$R9) -> 0.52388889 | W9: =IF(K9="",0,INDEX(ThuValue,MATCH(K9,ShiftList,0))*$R9) -> 0 | X9: =IF(M9="",0,INDEX(FriValue,MATCH(M9,ShiftList,0))*$R9) -> 0.98055556 | Y9: =IF(O9="",0,INDEX(SatValue,MATCH(O9,ShiftList,0))*$R9) -> 0.935
A10: Employee 06 | B10: Sales Assistant | C10: 10:00-19:00 | D10: =IF(S10=0,0,S10/S$35*C$2) -> 600.35021 | E10: 10:00-19:00 | F10: =IF(T10=0,0,T10/T$35*E$2) -> 705.16159 | H10: =IF(U10=0,0,U10/U$35*G$2) -> 0 | I10: 11:30-20:30 | J10: =IF(V10=0,0,V10/V$35*I$2) -> 663.19944 | K10: 10:00-19:00 | L10: =IF(W10=0,0,W10/W$35*K$2) -> 659.11039 | M10: 13:30-20:30 | N10: =IF(X10=0,0,X10/X$35*M$2) -> 987.26011 | O10: 8:00-17:00 | P10: =IF(Y10=0,0,Y10/Y$35*O$2) -> 719.39974 | Q10: =SUM(D10,F10,H10,J10,L10,N10,P10) -> 4334.4815 | R10: =IFERROR(INDEX(RoleFactor,MATCH(B10,RoleList,0)),1) -> 1 | S10: =IF(C10="",0,INDEX(SunValue,MATCH(C10,ShiftList,0))*$R10) -> 0.66666667 | T10: =IF(E10="",0,INDEX(MonValue,MATCH(E10,ShiftList,0))*$R10) -> 1.02 | U10: =IF(G10="",0,INDEX(TueValue,MATCH(G10,ShiftList,0))*$R10) -> 0 | V10: =IF(I10="",0,INDEX(WedValue,MATCH(I10,ShiftList,0))*$R10) -> 0.96888889 | W10: =IF(K10="",0,INDEX(ThuValue,MATCH(K10,ShiftList,0))*$R10) -> 1.0111111 | X10: =IF(M10="",0,INDEX(FriValue,MATCH(M10,ShiftList,0))*$R10) -> 0.79276786 | Y10: =IF(O10="",0,INDEX(SatValue,MATCH(O10,ShiftList,0))*$R10) -> 0.84
A11: Employee 07 | B11: Sales Assistant | C11: 13:30-20:30 | D11: =IF(S11=0,0,S11/S$35*C$2) -> 432.21195 | E11: 10:00-14:30 | F11: =IF(T11=0,0,T11/T$35*E$2) -> 362.18267 | H11: =IF(U11=0,0,U11/U$35*G$2) -> 0 | I11: 12:30-19:00 | J11: =IF(V11=0,0,V11/V$35*I$2) -> 540.61929 | K11: 10:00-14:30 | L11: =IF(W11=0,0,W11/W$35*K$2) -> 325.93371 | N11: =IF(X11=0,0,X11/X$35*M$2) -> 0 | O11: 11:30-20:30 | P11: =IF(Y11=0,0,Y11/Y$35*O$2) -> 800.76042 | Q11: =SUM(D11,F11,H11,J11,L11,N11,P11) -> 2461.708 | R11: =IFERROR(INDEX(RoleFactor,MATCH(B11,RoleList,0)),1) -> 1 | S11: =IF(C11="",0,INDEX(SunValue,MATCH(C11,ShiftList,0))*$R11) -> 0.47995536 | T11: =IF(E11="",0,INDEX(MonValue,MATCH(E11,ShiftList,0))*$R11) -> 0.52388889 | U11: =IF(G11="",0,INDEX(TueValue,MATCH(G11,ShiftList,0))*$R11) -> 0 | V11: =IF(I11="",0,INDEX(WedValue,MATCH(I11,ShiftList,0))*$R11) -> 0.78980769 | W11: =IF(K11="",0,INDEX(ThuValue,MATCH(K11,ShiftList,0))*$R11) -> 0.5 | X11: =IF(M11="",0,INDEX(FriValue,MATCH(M11,ShiftList,0))*$R11) -> 0 | Y11: =IF(O11="",0,INDEX(SatValue,MATCH(O11,ShiftList,0))*$R11) -> 0.935
A12: Employee 08 | B12: Senior Manager | D12: =IF(S12=0,0,S12/S$35*C$2) -> 0 | F12: =IF(T12=0,0,T12/T$35*E$2) -> 0 | G12: 12:30-19:00 | H12: =IF(U12=0,0,U12/U$35*G$2) -> 547.70953 | I12: 12:30-19:00 | J12: =IF(V12=0,0,V12/V$35*I$2) -> 432.49543 | K12: 12:30-19:00 | L12: =IF(W12=0,0,W12/W$35*K$2) -> 412.48165 | M12: 10:00-19:00 | N12: =IF(X12=0,0,X12/X$35*M$2) -> 992.94565 | O12: 10:00-19:00 | P12: =IF(Y12=0,0,Y12/Y$35*O$2) -> 709.50323 | Q12: =SUM(D12,F12,H12,J12,L12,N12,P12) -> 3095.1355 | R12: =IFERROR(INDEX(RoleFactor,MATCH(B12,RoleList,0)),1) -> 0.8 | S12: =IF(C12="",0,INDEX(SunValue,MATCH(C12,ShiftList,0))*$R12) -> 0 | T12: =IF(E12="",0,INDEX(MonValue,MATCH(E12,ShiftList,0))*$R12) -> 0 | U12: =IF(G12="",0,INDEX(TueValue,MATCH(G12,ShiftList,0))*$R12) -> 0.63184615 | V12: =IF(I12="",0,INDEX(WedValue,MATCH(I12,ShiftList,0))*$R12) -> 0.63184615 | W12: =IF(K12="",0,INDEX(ThuValue,MATCH(K12,ShiftList,0))*$R12) -> 0.63276923 | X12: =IF(M12="",0,INDEX(FriValue,MATCH(M12,ShiftList,0))*$R12) -> 0.79733333 | Y12: =IF(O12="",0,INDEX(SatValue,MATCH(O12,ShiftList,0))*$R12) -> 0.82844444
A13: Employee 09 | C13: 13:30-20:30 | D13: =IF(S13=0,0,S13/S$35*C$2) -> 432.21195 | F13: =IF(T13=0,0,T13/T$35*E$2) -> 0 | H13: =IF(U13=0,0,U13/U$35*G$2) -> 0 | I13: 13:30-20:30 | J13: =IF(V13=0,0,V13/V$35*I$2) -> 513.2489 | K13: 12:30-19:00 | L13: =IF(W13=0,0,W13/W$35*K$2) -> 515.60206 | N13: =IF(X13=0,0,X13/X$35*M$2) -> 0 | O13: 10:00-17:00 | P13: =IF(Y13=0,0,Y13/Y$35*O$2) -> 751.5158 | Q13: =SUM(D13,F13,H13,J13,L13,N13,P13) -> 2212.5787 | R13: =IFERROR(INDEX(RoleFactor,MATCH(B13,RoleList,0)),1) -> 1 | S13: =IF(C13="",0,INDEX(SunValue,MATCH(C13,ShiftList,0))*$R13) -> 0.47995536 | T13: =IF(E13="",0,INDEX(MonValue,MATCH(E13,ShiftList,0))*$R13) -> 0 | U13: =IF(G13="",0,INDEX(TueValue,MATCH(G13,ShiftList,0))*$R13) -> 0 | V13: =IF(I13="",0,INDEX(WedValue,MATCH(I13,ShiftList,0))*$R13) -> 0.74982143 | W13: =IF(K13="",0,INDEX(ThuValue,MATCH(K13,ShiftList,0))*$R13) -> 0.79096154 | X13: =IF(M13="",0,INDEX(FriValue,MATCH(M13,ShiftList,0))*$R13) -> 0 | Y13: =IF(O13="",0,INDEX(SatValue,MATCH(O13,ShiftList,0))*$R13) -> 0.8775
A14: Employee 10 | C14: 12:30-19:00 | D14: =IF(S14=0,0,S14/S$35*C$2) -> 557.97934 | E14: 8:00-17:00 | F14: =IF(T14=0,0,T14/T$35*E$2) -> 540.77752 | G14: 8:00-17:00 | H14: =IF(U14=0,0,U14/U$35*G$2) -> 678.06152 | I14: 12:30-19:00 | J14: =IF(V14=0,0,V14/V$35*I$2) -> 540.61929 | K14: 13:30-20:30 | L14: =IF(W14=0,0,W14/W$35*K$2) -> 500.51195 | M14: 8:00-17:00 | N14: =IF(X14=0,0,X14/X$35*M$2) -> 903.5584 | O14: 10:00-19:00 | P14: =IF(Y14=0,0,Y14/Y$35*O$2) -> 886.87904 | Q14: =SUM(D14,F14,H14,J14,L14,N14,P14) -> 4608.3871 | R14: =IFERROR(INDEX(RoleFactor,MATCH(B14,RoleList,0)),1) -> 1 | S14: =IF(C14="",0,INDEX(SunValue,MATCH(C14,ShiftList,0))*$R14) -> 0.61961538 | T14: =IF(E14="",0,INDEX(MonValue,MATCH(E14,ShiftList,0))*$R14) -> 0.78222222 | U14: =IF(G14="",0,INDEX(TueValue,MATCH(G14,ShiftList,0))*$R14) -> 0.78222222 | V14: =IF(I14="",0,INDEX(WedValue,MATCH(I14,ShiftList,0))*$R14) -> 0.78980769 | W14: =IF(K14="",0,INDEX(ThuValue,MATCH(K14,ShiftList,0))*$R14) -> 0.7678125 | X14: =IF(M14="",0,INDEX(FriValue,MATCH(M14,ShiftList,0))*$R14) -> 0.72555556 | Y14: =IF(O14="",0,INDEX(SatValue,MATCH(O14,ShiftList,0))*$R14) -> 1.0355556
D15: =IF(S15=0,0,S15/S$35*C$2) -> 0 | F15: =IF(T15=0,0,T15/T$35*E$2) -> 0 | H15: =IF(U15=0,0,U15/U$35*G$2) -> 0 | J15: =IF(V15=0,0,V15/V$35*I$2) -> 0 | L15: =IF(W15=0,0,W15/W$35*K$2) -> 0 | N15: =IF(X15=0,0,X15/X$35*M$2) -> 0 | P15: =IF(Y15=0,0,Y15/Y$35*O$2) -> 0 | Q15: =SUM(D15,F15,H15,J15,L15,N15,P15) -> 0 | R15: =IFERROR(INDEX(RoleFactor,MATCH(B15,RoleList,0)),1) -> 1 | S15: =IF(C15="",0,INDEX(SunValue,MATCH(C15,ShiftList,0))*$R15) -> 0 | T15: =IF(E15="",0,INDEX(MonValue,MATCH(E15,ShiftList,0))*$R15) -> 0 | U15: =IF(G15="",0,INDEX(TueValue,MATCH(G15,ShiftList,0))*$R15) -> 0 | V15: =IF(I15="",0,INDEX(WedValue,MATCH(I15,ShiftList,0))*$R15) -> 0 | W15: =IF(K15="",0,INDEX(ThuValue,MATCH(K15,ShiftList,0))*$R15) -> 0 | X15: =IF(M15="",0,INDEX(FriValue,MATCH(M15,ShiftList,0))*$R15) -> 0 | Y15: =IF(O15="",0,INDEX(SatValue,MATCH(O15,ShiftList,0))*$R15) -> 0
D16: =IF(S16=0,0,S16/S$35*C$2) -> 0 | F16: =IF(T16=0,0,T16/T$35*E$2) -> 0 | H16: =IF(U16=0,0,U16/U$35*G$2) -> 0 | J16: =IF(V16=0,0,V16/V$35*I$2) -> 0 | L16: =IF(W16=0,0,W16/W$35*K$2) -> 0 | N16: =IF(X16=0,0,X16/X$35*M$2) -> 0 | P16: =IF(Y16=0,0,Y16/Y$35*O$2) -> 0 | Q16: =SUM(D16,F16,H16,J16,L16,N16,P16) -> 0 | R16: =IFERROR(INDEX(RoleFactor,MATCH(B16,RoleList,0)),1) -> 1 | S16: =IF(C16="",0,INDEX(SunValue,MATCH(C16,ShiftList,0))*$R16) -> 0 | T16: =IF(E16="",0,INDEX(MonValue,MATCH(E16,ShiftList,0))*$R16) -> 0 | U16: =IF(G16="",0,INDEX(TueValue,MATCH(G16,ShiftList,0))*$R16) -> 0 | V16: =IF(I16="",0,INDEX(WedValue,MATCH(I16,ShiftList,0))*$R16) -> 0 | W16: =IF(K16="",0,INDEX(ThuValue,MATCH(K16,ShiftList,0))*$R16) -> 0 | X16: =IF(M16="",0,INDEX(FriValue,MATCH(M16,ShiftList,0))*$R16) -> 0 | Y16: =IF(O16="",0,INDEX(SatValue,MATCH(O16,ShiftList,0))*$R16) -> 0
D17: =IF(S17=0,0,S17/S$35*C$2) -> 0 | F17: =IF(T17=0,0,T17/T$35*E$2) -> 0 | H17: =IF(U17=0,0,U17/U$35*G$2) -> 0 | J17: =IF(V17=0,0,V17/V$35*I$2) -> 0 | L17: =IF(W17=0,0,W17/W$35*K$2) -> 0 | N17: =IF(X17=0,0,X17/X$35*M$2) -> 0 | P17: =IF(Y17=0,0,Y17/Y$35*O$2) -> 0 | Q17: =SUM(D17,F17,H17,J17,L17,N17,P17) -> 0 | R17: =IFERROR(INDEX(RoleFactor,MATCH(B17,RoleList,0)),1) -> 1 | S17: =IF(C17="",0,INDEX(SunValue,MATCH(C17,ShiftList,0))*$R17) -> 0 | T17: =IF(E17="",0,INDEX(MonValue,MATCH(E17,ShiftList,0))*$R17) -> 0 | U17: =IF(G17="",0,INDEX(TueValue,MATCH(G17,ShiftList,0))*$R17) -> 0 | V17: =IF(I17="",0,INDEX(WedValue,MATCH(I17,ShiftList,0))*$R17) -> 0 | W17: =IF(K17="",0,INDEX(ThuValue,MATCH(K17,ShiftList,0))*$R17) -> 0 | X17: =IF(M17="",0,INDEX(FriValue,MATCH(M17,ShiftList,0))*$R17) -> 0 | Y17: =IF(O17="",0,INDEX(SatValue,MATCH(O17,ShiftList,0))*$R17) -> 0
D18: =IF(S18=0,0,S18/S$35*C$2) -> 0 | F18: =IF(T18=0,0,T18/T$35*E$2) -> 0 | H18: =IF(U18=0,0,U18/U$35*G$2) -> 0 | J18: =IF(V18=0,0,V18/V$35*I$2) -> 0 | L18: =IF(W18=0,0,W18/W$35*K$2) -> 0 | N18: =IF(X18=0,0,X18/X$35*M$2) -> 0 | P18: =IF(Y18=0,0,Y18/Y$35*O$2) -> 0 | Q18: =SUM(D18,F18,H18,J18,L18,N18,P18) -> 0 | R18: =IFERROR(INDEX(RoleFactor,MATCH(B18,RoleList,0)),1) -> 1 | S18: =IF(C18="",0,INDEX(SunValue,MATCH(C18,ShiftList,0))*$R18) -> 0 | T18: =IF(E18="",0,INDEX(MonValue,MATCH(E18,ShiftList,0))*$R18) -> 0 | U18: =IF(G18="",0,INDEX(TueValue,MATCH(G18,ShiftList,0))*$R18) -> 0 | V18: =IF(I18="",0,INDEX(WedValue,MATCH(I18,ShiftList,0))*$R18) -> 0 | W18: =IF(K18="",0,INDEX(ThuValue,MATCH(K18,ShiftList,0))*$R18) -> 0 | X18: =IF(M18="",0,INDEX(FriValue,MATCH(M18,ShiftList,0))*$R18) -> 0 | Y18: =IF(O18="",0,INDEX(SatValue,MATCH(O18,ShiftList,0))*$R18) -> 0
D19: =IF(S19=0,0,S19/S$35*C$2) -> 0 | F19: =IF(T19=0,0,T19/T$35*E$2) -> 0 | H19: =IF(U19=0,0,U19/U$35*G$2) -> 0 | J19: =IF(V19=0,0,V19/V$35*I$2) -> 0 | L19: =IF(W19=0,0,W19/W$35*K$2) -> 0 | N19: =IF(X19=0,0,X19/X$35*M$2) -> 0 | P19: =IF(Y19=0,0,Y19/Y$35*O$2) -> 0 | Q19: =SUM(D19,F19,H19,J19,L19,N19,P19) -> 0 | R19: =IFERROR(INDEX(RoleFactor,MATCH(B19,RoleList,0)),1) -> 1 | S19: =IF(C19="",0,INDEX(SunValue,MATCH(C19,ShiftList,0))*$R19) -> 0 | T19: =IF(E19="",0,INDEX(MonValue,MATCH(E19,ShiftList,0))*$R19) -> 0 | U19: =IF(G19="",0,INDEX(TueValue,MATCH(G19,ShiftList,0))*$R19) -> 0 | V19: =IF(I19="",0,INDEX(WedValue,MATCH(I19,ShiftList,0))*$R19) -> 0 | W19: =IF(K19="",0,INDEX(ThuValue,MATCH(K19,ShiftList,0))*$R19) -> 0 | X19: =IF(M19="",0,INDEX(FriValue,MATCH(M19,ShiftList,0))*$R19) -> 0 | Y19: =IF(O19="",0,INDEX(SatValue,MATCH(O19,ShiftList,0))*$R19) -> 0
D20: =IF(S20=0,0,S20/S$35*C$2) -> 0 | F20: =IF(T20=0,0,T20/T$35*E$2) -> 0 | H20: =IF(U20=0,0,U20/U$35*G$2) -> 0 | J20: =IF(V20=0,0,V20/V$35*I$2) -> 0 | L20: =IF(W20=0,0,W20/W$35*K$2) -> 0 | N20: =IF(X20=0,0,X20/X$35*M$2) -> 0 | P20: =IF(Y20=0,0,Y20/Y$35*O$2) -> 0 | Q20: =SUM(D20,F20,H20,J20,L20,N20,P20) -> 0 | R20: =IFERROR(INDEX(RoleFactor,MATCH(B20,RoleList,0)),1) -> 1 | S20: =IF(C20="",0,INDEX(SunValue,MATCH(C20,ShiftList,0))*$R20) -> 0 | T20: =IF(E20="",0,INDEX(MonValue,MATCH(E20,ShiftList,0))*$R20) -> 0 | U20: =IF(G20="",0,INDEX(TueValue,MATCH(G20,ShiftList,0))*$R20) -> 0 | V20: =IF(I20="",0,INDEX(WedValue,MATCH(I20,ShiftList,0))*$R20) -> 0 | W20: =IF(K20="",0,INDEX(ThuValue,MATCH(K20,ShiftList,0))*$R20) -> 0 | X20: =IF(M20="",0,INDEX(FriValue,MATCH(M20,ShiftList,0))*$R20) -> 0 | Y20: =IF(O20="",0,INDEX(SatValue,MATCH(O20,ShiftList,0))*$R20) -> 0
D21: =IF(S21=0,0,S21/S$35*C$2) -> 0 | F21: =IF(T21=0,0,T21/T$35*E$2) -> 0 | H21: =IF(U21=0,0,U21/U$35*G$2) -> 0 | J21: =IF(V21=0,0,V21/V$35*I$2) -> 0 | L21: =IF(W21=0,0,W21/W$35*K$2) -> 0 | N21: =IF(X21=0,0,X21/X$35*M$2) -> 0 | P21: =IF(Y21=0,0,Y21/Y$35*O$2) -> 0 | Q21: =SUM(D21,F21,H21,J21,L21,N21,P21) -> 0 | R21: =IFERROR(INDEX(RoleFactor,MATCH(B21,RoleList,0)),1) -> 1 | S21: =IF(C21="",0,INDEX(SunValue,MATCH(C21,ShiftList,0))*$R21) -> 0 | T21: =IF(E21="",0,INDEX(MonValue,MATCH(E21,ShiftList,0))*$R21) -> 0 | U21: =IF(G21="",0,INDEX(TueValue,MATCH(G21,ShiftList,0))*$R21) -> 0 | V21: =IF(I21="",0,INDEX(WedValue,MATCH(I21,ShiftList,0))*$R21) -> 0 | W21: =IF(K21="",0,INDEX(ThuValue,MATCH(K21,ShiftList,0))*$R21) -> 0 | X21: =IF(M21="",0,INDEX(FriValue,MATCH(M21,ShiftList,0))*$R21) -> 0 | Y21: =IF(O21="",0,INDEX(SatValue,MATCH(O21,ShiftList,0))*$R21) -> 0
D22: =IF(S22=0,0,S22/S$35*C$2) -> 0 | F22: =IF(T22=0,0,T22/T$35*E$2) -> 0 | H22: =IF(U22=0,0,U22/U$35*G$2) -> 0 | J22: =IF(V22=0,0,V22/V$35*I$2) -> 0 | L22: =IF(W22=0,0,W22/W$35*K$2) -> 0 | N22: =IF(X22=0,0,X22/X$35*M$2) -> 0 | P22: =IF(Y22=0,0,Y22/Y$35*O$2) -> 0 | Q22: =SUM(D22,F22,H22,J22,L22,N22,P22) -> 0 | R22: =IFERROR(INDEX(RoleFactor,MATCH(B22,RoleList,0)),1) -> 1 | S22: =IF(C22="",0,INDEX(SunValue,MATCH(C22,ShiftList,0))*$R22) -> 0 | T22: =IF(E22="",0,INDEX(MonValue,MATCH(E22,ShiftList,0))*$R22) -> 0 | U22: =IF(G22="",0,INDEX(TueValue,MATCH(G22,ShiftList,0))*$R22) -> 0 | V22: =IF(I22="",0,INDEX(WedValue,MATCH(I22,ShiftList,0))*$R22) -> 0 | W22: =IF(K22="",0,INDEX(ThuValue,MATCH(K22,ShiftList,0))*$R22) -> 0 | X22: =IF(M22="",0,INDEX(FriValue,MATCH(M22,ShiftList,0))*$R22) -> 0 | Y22: =IF(O22="",0,INDEX(SatValue,MATCH(O22,ShiftList,0))*$R22) -> 0
D23: =IF(S23=0,0,S23/S$35*C$2) -> 0 | F23: =IF(T23=0,0,T23/T$35*E$2) -> 0 | H23: =IF(U23=0,0,U23/U$35*G$2) -> 0 | J23: =IF(V23=0,0,V23/V$35*I$2) -> 0 | L23: =IF(W23=0,0,W23/W$35*K$2) -> 0 | N23: =IF(X23=0,0,X23/X$35*M$2) -> 0 | P23: =IF(Y23=0,0,Y23/Y$35*O$2) -> 0 | Q23: =SUM(D23,F23,H23,J23,L23,N23,P23) -> 0 | R23: =IFERROR(INDEX(RoleFactor,MATCH(B23,RoleList,0)),1) -> 1 | S23: =IF(C23="",0,INDEX(SunValue,MATCH(C23,ShiftList,0))*$R23) -> 0 | T23: =IF(E23="",0,INDEX(MonValue,MATCH(E23,ShiftList,0))*$R23) -> 0 | U23: =IF(G23="",0,INDEX(TueValue,MATCH(G23,ShiftList,0))*$R23) -> 0 | V23: =IF(I23="",0,INDEX(WedValue,MATCH(I23,ShiftList,0))*$R23) -> 0 | W23: =IF(K23="",0,INDEX(ThuValue,MATCH(K23,ShiftList,0))*$R23) -> 0 | X23: =IF(M23="",0,INDEX(FriValue,MATCH(M23,ShiftList,0))*$R23) -> 0 | Y23: =IF(O23="",0,INDEX(SatValue,MATCH(O23,ShiftList,0))*$R23) -> 0
D24: =IF(S24=0,0,S24/S$35*C$2) -> 0 | F24: =IF(T24=0,0,T24/T$35*E$2) -> 0 | H24: =IF(U24=0,0,U24/U$35*G$2) -> 0 | J24: =IF(V24=0,0,V24/V$35*I$2) -> 0 | L24: =IF(W24=0,0,W24/W$35*K$2) -> 0 | N24: =IF(X24=0,0,X24/X$35*M$2) -> 0 | P24: =IF(Y24=0,0,Y24/Y$35*O$2) -> 0 | Q24: =SUM(D24,F24,H24,J24,L24,N24,P24) -> 0 | R24: =IFERROR(INDEX(RoleFactor,MATCH(B24,RoleList,0)),1) -> 1 | S24: =IF(C24="",0,INDEX(SunValue,MATCH(C24,ShiftList,0))*$R24) -> 0 | T24: =IF(E24="",0,INDEX(MonValue,MATCH(E24,ShiftList,0))*$R24) -> 0 | U24: =IF(G24="",0,INDEX(TueValue,MATCH(G24,ShiftList,0))*$R24) -> 0 | V24: =IF(I24="",0,INDEX(WedValue,MATCH(I24,ShiftList,0))*$R24) -> 0 | W24: =IF(K24="",0,INDEX(ThuValue,MATCH(K24,ShiftList,0))*$R24) -> 0 | X24: =IF(M24="",0,INDEX(FriValue,MATCH(M24,ShiftList,0))*$R24) -> 0 | Y24: =IF(O24="",0,INDEX(SatValue,MATCH(O24,ShiftList,0))*$R24) -> 0
D25: =IF(S25=0,0,S25/S$35*C$2) -> 0 | F25: =IF(T25=0,0,T25/T$35*E$2) -> 0 | H25: =IF(U25=0,0,U25/U$35*G$2) -> 0 | J25: =IF(V25=0,0,V25/V$35*I$2) -> 0 | L25: =IF(W25=0,0,W25/W$35*K$2) -> 0 | N25: =IF(X25=0,0,X25/X$35*M$2) -> 0 | P25: =IF(Y25=0,0,Y25/Y$35*O$2) -> 0 | Q25: =SUM(D25,F25,H25,J25,L25,N25,P25) -> 0 | R25: =IFERROR(INDEX(RoleFactor,MATCH(B25,RoleList,0)),1) -> 1 | S25: =IF(C25="",0,INDEX(SunValue,MATCH(C25,ShiftList,0))*$R25) -> 0 | T25: =IF(E25="",0,INDEX(MonValue,MATCH(E25,ShiftList,0))*$R25) -> 0 | U25: =IF(G25="",0,INDEX(TueValue,MATCH(G25,ShiftList,0))*$R25) -> 0 | V25: =IF(I25="",0,INDEX(WedValue,MATCH(I25,ShiftList,0))*$R25) -> 0 | W25: =IF(K25="",0,INDEX(ThuValue,MATCH(K25,ShiftList,0))*$R25) -> 0 | X25: =IF(M25="",0,INDEX(FriValue,MATCH(M25,ShiftList,0))*$R25) -> 0 | Y25: =IF(O25="",0,INDEX(SatValue,MATCH(O25,ShiftList,0))*$R25) -> 0
D26: =IF(S26=0,0,S26/S$35*C$2) -> 0 | F26: =IF(T26=0,0,T26/T$35*E$2) -> 0 | H26: =IF(U26=0,0,U26/U$35*G$2) -> 0 | J26: =IF(V26=0,0,V26/V$35*I$2) -> 0 | L26: =IF(W26=0,0,W26/W$35*K$2) -> 0 | N26: =IF(X26=0,0,X26/X$35*M$2) -> 0 | P26: =IF(Y26=0,0,Y26/Y$35*O$2) -> 0 | Q26: =SUM(D26,F26,H26,J26,L26,N26,P26) -> 0 | R26: =IFERROR(INDEX(RoleFactor,MATCH(B26,RoleList,0)),1) -> 1 | S26: =IF(C26="",0,INDEX(SunValue,MATCH(C26,ShiftList,0))*$R26) -> 0 | T26: =IF(E26="",0,INDEX(MonValue,MATCH(E26,ShiftList,0))*$R26) -> 0 | U26: =IF(G26="",0,INDEX(TueValue,MATCH(G26,ShiftList,0))*$R26) -> 0 | V26: =IF(I26="",0,INDEX(WedValue,MATCH(I26,ShiftList,0))*$R26) -> 0 | W26: =IF(K26="",0,INDEX(ThuValue,MATCH(K26,ShiftList,0))*$R26) -> 0 | X26: =IF(M26="",0,INDEX(FriValue,MATCH(M26,ShiftList,0))*$R26) -> 0 | Y26: =IF(O26="",0,INDEX(SatValue,MATCH(O26,ShiftList,0))*$R26) -> 0
... D34: =IF(S34=0,0,S34/S$35*C$2) -> 0 | F34: =IF(T34=0,0,T34/T$35*E$2) -> 0 | H34: =IF(U34=0,0,U34/U$35*G$2) -> 0 | J34: =IF(V34=0,0,V34/V$35*I$2) -> 0 | L34: =IF(W34=0,0,W34/W$35*K$2) -> 0 | N34: =IF(X34=0,0,X34/X$35*M$2) -> 0 | P34: =IF(Y34=0,0,Y34/Y$35*O$2) -> 0 | Q34: =SUM(D34,F34,H34,J34,L34,N34,P34) -> 0 | R34: =IFERROR(INDEX(RoleFactor,MATCH(B34,RoleList,0)),1) -> 1 | S34: =IF(C34="",0,INDEX(SunValue,MATCH(C34,ShiftList,0))*$R34) -> 0 | T34: =IF(E34="",0,INDEX(MonValue,MATCH(E34,ShiftList,0))*$R34) -> 0 | U34: =IF(G34="",0,INDEX(TueValue,MATCH(G34,ShiftList,0))*$R34) -> 0 | V34: =IF(I34="",0,INDEX(WedValue,MATCH(I34,ShiftList,0))*$R34) -> 0 | W34: =IF(K34="",0,INDEX(ThuValue,MATCH(K34,ShiftList,0))*$R34) -> 0 | X34: =IF(M34="",0,INDEX(FriValue,MATCH(M34,ShiftList,0))*$R34) -> 0 | Y34: =IF(O34="",0,INDEX(SatValue,MATCH(O34,ShiftList,0))*$R34) -> 0
R35: Total weight | S35: =SUM(S5:S34) -> 3.5534815 | T35: =SUM(T5:T34) -> 5.9305556 | U35: =SUM(U5:U34) -> 4.4991001 | V35: =SUM(V5:V34) -> 5.8437256 | W35: =SUM(W5:W34) -> 6.5964334 | X35: =SUM(X5:X34) -> 5.4603861 | Y35: =SUM(Y5:Y34) -> 8.4070089
A36: Role Factors | B36: See Settings sheet
A37: Shift Weights | B37: See Settings sheet

Sheet Settings
A1: Settings - Target Allocation
A2: Yellow cells = inputs you can change. Blue/grey cells = calculated, leave alone.
A3: How targets are calculated
A4: 1. For each hour of a shift, count the fraction of that hour worked (clipped to trading hours) x that hour's weight
A5: 2. Sum those across the shift, then scale down for lunch: lunch minutes / rostered shift minutes
A6: 3. Shift value = that result / standard shift length x role factor = person weight
A7: 4. Target = person weight / total weight of everyone working that day x that day's target
A9: Trading hours (time outside these hours is not counted)
B10: Sun | C10: Mon | D10: Tue | E10: Wed | F10: Thu | G10: Fri | H10: Sat
A11: Opens (hour) | B11: 12 | C11: 10 | D11: 10 | E11: 10 | F11: 10 | G11: 10 | H11: 10
A12: Closes (hour) | B12: 18 | C12: 20 | D12: 20 | E12: 20 | F12: 20 | G12: 20 | H12: 20
A13: Hours are 24-hour decimals (14.5 = 14:30).
A14: Shifts (this list also feeds the shift dropdown)
A15: Shift | B15: Start (hour) | C15: End (hour) | D15: Hours | E15: Lunch | F15: Lunch fraction
A16: 8:00-17:00 | B16: 8 | C16: 17 | D16: =C16-B16 -> 9 | E16: =IF(D16>$B$36,$B$37,$B$38) -> 1 | F16: =IF(D16=0,0,E16/D16) -> 0.11111111
A17: 10:00-19:00 | B17: 10 | C17: 19 | D17: =C17-B17 -> 9 | E17: =IF(D17>$B$36,$B$37,$B$38) -> 1 | F17: =IF(D17=0,0,E17/D17) -> 0.11111111
A18: 10:00-14:30 | B18: 10 | C18: 14.5 | D18: =C18-B18 -> 4.5 | E18: =IF(D18>$B$36,$B$37,$B$38) -> 0.5 | F18: =IF(D18=0,0,E18/D18) -> 0.11111111
A19: 10:00-17:00 | B19: 10 | C19: 17 | D19: =C19-B19 -> 7 | E19: =IF(D19>$B$36,$B$37,$B$38) -> 0.5 | F19: =IF(D19=0,0,E19/D19) -> 0.071428571
A20: 12:30-19:00 | B20: 12.5 | C20: 19 | D20: =C20-B20 -> 6.5 | E20: =IF(D20>$B$36,$B$37,$B$38) -> 0.5 | F20: =IF(D20=0,0,E20/D20) -> 0.076923077
A21: 11:30-20:30 | B21: 11.5 | C21: 20.5 | D21: =C21-B21 -> 9 | E21: =IF(D21>$B$36,$B$37,$B$38) -> 1 | F21: =IF(D21=0,0,E21/D21) -> 0.11111111
A22: 13:30-20:30 | B22: 13.5 | C22: 20.5 | D22: =C22-B22 -> 7 | E22: =IF(D22>$B$36,$B$37,$B$38) -> 0.5 | F22: =IF(D22=0,0,E22/D22) -> 0.071428571
A23: To add a shift, insert a row inside the table and copy the blue formulas down (also inside Shift_Values).
A25: Role factors
A26: Role | B26: Factor
A27: Sales Assistant | B27: 1
A28: Manager | B28: 0.88
A29: Senior Manager | B29: 0.8
A30: A blank or unlisted role counts as x1.00.
A32: Standard shift length
A33: Standard shift length (hours) | B33: 8
A35: Lunch break (deducted proportionally from each shift)
A36: Shifts longer than (hours) | B36: 8
A37: Lunch on those shifts (hours) | B37: 1
A38: Lunch on shorter shifts (hours) | B38: 0.5
A39: Hourly weight (edit once you have real hour-by-hour sales data)
A40: Hour starts at | B40: Sun | C40: Mon | D40: Tue | E40: Wed | F40: Thu | G40: Fri | H40: Sat
A41: 0 | B41: 1 | C41: 1 | D41: 1 | E41: 1 | F41: 1 | G41: 1 | H41: 1
A42: 1 | B42: 1 | C42: 1 | D42: 1 | E42: 1 | F42: 1 | G42: 1 | H42: 1
A43: 2 | B43: 1 | C43: 1 | D43: 1 | E43: 1 | F43: 1 | G43: 1 | H43: 1
A44: 3 | B44: 1 | C44: 1 | D44: 1 | E44: 1 | F44: 1 | G44: 1 | H44: 1
...

Sheet Shift_Values
A1: Shift values by day - calculation only
A2: Nothing to edit here. Grid A sums each shift's hour-by-hour weight inside trading hours; Grid B scales it for lunch and the standard length.
A4: A. Weighted hours in trading (before lunch)
A5: Shift | B5: Sun | C5: Mon | D5: Tue | E5: Wed | F5: Thu | G5: Fri | H5: Sat
A6: =Settings!$A$16 -> 8:00-17:00 | B6: =SUMPRODUCT((((((MIN(Settings!$C$16,Settings!B$12)+(Settings!$A$41:$A$64+1)-ABS(MIN(Settings!$C$16,Settings!B$12)-(Settings!$A$41:$A$64+1)))/2)-((MAX(Settings!$B$16,Settings!B$11)+Settings!$A$41:$A$64+ABS(MAX(Settings!$B$16,Settings!B$11)-Settings!$A$41:$A$64))/2))+ABS((((MIN(Settings!$C$16,Settings!B$12)+(Settings!$A$41:$A$64+1)-ABS(MIN(Settings!$C$16,Settings!B$12)-(Settings!$A$41:$A$64+1)))/2)-((MAX(Settings!$B$16,Settings!B$11)+Settings!$A$41:$A$64+ABS(MAX(Settings!$B$16,Settings!B$11)-Settings!$A$41:$A$64))/2))))/2),Settings!B$41:B$64) -> 5.32 | C6: =SUMPRODUCT((((((MIN(Settings!$C$16,Settings!C$12)+(Settings!$A$41:$A$64+1)-ABS(MIN(Settings!$C$16,Settings!C$12)-(Settings!$A$41:$A$64+1)))/2)-((MAX(Settings!$B$16,Settings!C$11)+Settings!$A$41:$A$64+ABS(MAX(Settings!$B$16,Settings!C$11)-Settings!$A$41:$A$64))/2))+ABS((((MIN(Settings!$C$16,Settings!C$12)+(Settings!$A$41:$A$64+1)-ABS(MIN(Settings!$C$16,Settings!C$12)-(Settings!$A$41:$A$64+1)))/2)-((MAX(Settings!$B$16,Settings!C$11)+Settings!$A$41:$A$64+ABS(MAX(Settings!$B$16,Settings!C$11)-Settings!$A$41:$A$64))/2))))/2),Settings!C$41:C$64) -> 7.04 | D6: =SUMPRODUCT((((((MIN(Settings!$C$16,Settings!D$12)+(Settings!$A$41:$A$64+1)-ABS(MIN(Settings!$C$16,Settings!D$12)-(Settings!$A$41:$A$64+1)))/2)-((MAX(Settings!$B$16,Settings!D$11)+Settings!$A$41:$A$64+ABS(MAX(Settings!$B$16,Settings!D$11)-Settings!$A$41:$A$64))/2))+ABS((((MIN(Settings!$C$16,Settings!D$12)+(Settings!$A$41:$A$64+1)-ABS(MIN(Settings!$C$16,Settings!D$12)-(Settings!$A$41:$A$64+1)))/2)-((MAX(Settings!$B$16,Settings!D$11)+Settings!$A$41:$A$64+ABS(MAX(Settings!$B$16,Settings!D$11)-Settings!$A$41:$A$64))/2))))/2),Settings!D$41:D$64) -> 7.04 | E6: =SUMPRODUCT((((((MIN(Settings!$C$16,Settings!E$12)+(Settings!$A$41:$A$64+1)-ABS(MIN(Settings!$C$16,Settings!E$12)-(Settings!$A$41:$A$64+1)))/2)-((MAX(Settings!$B$16,Settings!E$11)+Settings!$A$41:$A$64+ABS(MAX(Settings!$B$16,Settings!E$11)-Settings!$A$41:$A$64))/2))+ABS((((MIN(Settings!$C$16,Settings!E$12)+(Settings!$A$41:$A$64+1)-ABS(MIN(Settings!$C$16,Settings!E$12)-(Settings!$A$41:$A$64+1)))/2)-((MAX(Settings!$B$16,Settings!E$11)+Settings!$A$41:$A$64+ABS(MAX(Settings!$B$16,Settings!E$11)-Settings!$A$41:$A$64))/2))))/2),Settings!E$41:E$64) -> 7.04 | F6: =SUMPRODUCT((((((MIN(Settings!$C$16,Settings!F$12)+(Settings!$A$41:$A$64+1)-ABS(MIN(Settings!$C$16,Settings!F$12)-(Settings!$A$41:$A$64+1)))/2)-((MAX(Settings!$B$16,Settings!F$11)+Settings!$A$41:$A$64+ABS(MAX(Settings!$B$16,Settings!F$11)-Settings!$A$41:$A$64))/2))+ABS((((MIN(Settings!$C$16,Settings!F$12)+(Settings!$A$41:$A$64+1)-ABS(MIN(Settings!$C$16,Settings!F$12)-(Settings!$A$41:$A$64+1)))/2)-((MAX(Settings!$B$16,Settings!F$11)+Settings!$A$41:$A$64+ABS(MAX(Settings!$B$16,Settings!F$11)-Settings!$A$41:$A$64))/2))))/2),Settings!F$41:F$64) -> 6.84 | G6: =SUMPRODUCT((((((MIN(Settings!$C$16,Settings!G$12)+(Settings!$A$41:$A$64+1)-ABS(MIN(Settings!$C$16,Settings!G$12)-(Settings!$A$41:$A$64+1)))/2)-((MAX(Settings!$B$16,Settings!G$11)+Settings!$A$41:$A$64+ABS(MAX(Settings!$B$16,Settings!G$11)-Settings!$A$41:$A$64))/2))+ABS((((MIN(Settings!$C$16,Settings!G$12)+(Settings!$A$41:$A$64+1)-ABS(MIN(Settings!$C$16,Settings!G$12)-(Settings!$A$41:$A$64+1)))/2)-((MAX(Settings!$B$16,Settings!G$11)+Settings!$A$41:$A$64+ABS(MAX(Settings!$B$16,Settings!G$11)-Settings!$A$41:$A$64))/2))))/2),Settings!G$41:G$64) -> 6.53 | H6: =SUMPRODUCT((((((MIN(Settings!$C$16,Settings!H$12)+(Settings!$A$41:$A$64+1)-ABS(MIN(Settings!$C$16,Settings!H$12)-(Settings!$A$41:$A$64+1)))/2)-((MAX(Settings!$B$16,Settings!H$11)+Settings!$A$41:$A$64+ABS(MAX(Settings!$B$16,Settings!H$11)-Settings!$A$41:$A$64))/2))+ABS((((MIN(Settings!$C$16,Settings!H$12)+(Settings!$A$41:$A$64+1)-ABS(MIN(Settings!$C$16,Settings!H$12)-(Settings!$A$41:$A$64+1)))/2)-((MAX(Settings!$B$16,Settings!H$11)+Settings!$A$41:$A$64+ABS(MAX(Settings!$B$16,Settings!H$11)-Settings!$A$41:$A$64))/2))))/2),Settings!H$41:H$64) -> 7.56
A7: =Settings!$A$17 -> 10:00-19:00 | B7: =SUMPRODUCT((((((MIN(Settings!$C$17,Settings!B$12)+(Settings!$A$41:$A$64+1)-ABS(MIN(Settings!$C$17,Settings!B$12)-(Settings!$A$41:$A$64+1)))/2)-((MAX(Settings!$B$17,Settings!B$11)+Settings!$A$41:$A$64+ABS(MAX(Settings!$B$17,Settings!B$11)-Settings!$A$41:$A$64))/2))+ABS((((MIN(Settings!$C$17,Settings!B$12)+(Settings!$A$41:$A$64+1)-ABS(MIN(Settings!$C$17,Settings!B$12)-(Settings!$A$41:$A$64+1)))/2)-((MAX(Settings!$B$17,Settings!B$11)+Settings!$A$41:$A$64+ABS(MAX(Settings!$B$17,Settings!B$11)-Settings!$A$41:$A$64))/2))))/2),Settings!B$41:B$64) -> 6 | C7: =SUMPRODUCT((((((MIN(Settings!$C$17,Settings!C$12)+(Settings!$A$41:$A$64+1)-ABS(MIN(Settings!$C$17,Settings!C$12)-(Settings!$A$41:$A$64+1)))/2)-((MAX(Settings!$B$17,Settings!C$11)+Settings!$A$41:$A$64+ABS(MAX(Settings!$B$17,Settings!C$11)-Settings!$A$41:$A$64))/2))+ABS((((MIN(Settings!$C$17,Settings!C$12)+(Settings!$A$41:$A$64+1)-ABS(MIN(Settings!$C$17,Settings!C$12)-(Settings!$A$41:$A$64+1)))/2)-((MAX(Settings!$B$17,Settings!C$11)+Settings!$A$41:$A$64+ABS(MAX(Settings!$B$17,Settings!C$11)-Settings!$A$41:$A$64))/2))))/2),Settings!C$41:C$64) -> 9.18 | D7: =SUMPRODUCT((((((MIN(Settings!$C$17,Settings!D$12)+(Settings!$A$41:$A$64+1)-ABS(MIN(Settings!$C$17,Settings!D$12)-(Settings!$A$41:$A$64+1)))/2)-((MAX(Settings!$B$17,Settings!D$11)+Settings!$A$41:$A$64+ABS(MAX(Settings!$B$17,Settings!D$11)-Settings!$A$41:$A$64))/2))+ABS((((MIN(Settings!$C$17,Settings!D$12)+(Settings!$A$41:$A$64+1)-ABS(MIN(Settings!$C$17,Settings!D$12)-(Settings!$A$41:$A$64+1)))/2)-((MAX(Settings!$B$17,Settings!D$11)+Settings!$A$41:$A$64+ABS(MAX(Settings!$B$17,Settings!D$11)-Settings!$A$41:$A$64))/2))))/2),Settings!D$41:D$64) -> 9.18 | E7: =SUMPRODUCT((((((MIN(Settings!$C$17,Settings!E$12)+(Settings!$A$41:$A$64+1)-ABS(MIN(Settings!$C$17,Settings!E$12)-(Settings!$A$41:$A$64+1)))/2)-((MAX(Settings!$B$17,Settings!E$11)+Settings!$A$41:$A$64+ABS(MAX(Settings!$B$17,Settings!E$11)-Settings!$A$41:$A$64))/2))+ABS((((MIN(Settings!$C$17,Settings!E$12)+(Settings!$A$41:$A$64+1)-ABS(MIN(Settings!$C$17,Settings!E$12)-(Settings!$A$41:$A$64+1)))/2)-((MAX(Settings!$B$17,Settings!E$11)+Settings!$A$41:$A$64+ABS(MAX(Settings!$B$17,Settings!E$11)-Settings!$A$41:$A$64))/2))))/2),Settings!E$41:E$64) -> 9.18 | F7: =SUMPRODUCT((((((MIN(Settings!$C$17,Settings!F$12)+(Settings!$A$41:$A$64+1)-ABS(MIN(Settings!$C$17,Settings!F$12)-(Settings!$A$41:$A$64+1)))/2)-((MAX(Settings!$B$17,Settings!F$11)+Settings!$A$41:$A$64+ABS(MAX(Settings!$B$17,Settings!F$11)-Settings!$A$41:$A$64))/2))+ABS((((MIN(Settings!$C$17,Settings!F$12)+(Settings!$A$41:$A$64+1)-ABS(MIN(Settings!$C$17,Settings!F$12)-(Settings!$A$41:$A$64+1)))/2)-((MAX(Settings!$B$17,Settings!F$11)+Settings!$A$41:$A$64+ABS(MAX(Settings!$B$17,Settings!F$11)-Settings!$A$41:$A$64))/2))))/2),Settings!F$41:F$64) -> 9.1 | G7: =SUMPRODUCT((((((MIN(Settings!$C$17,Settings!G$12)+(Settings!$A$41:$A$64+1)-ABS(MIN(Settings!$C$17,Settings!G$12)-(Settings!$A$41:$A$64+1)))/2)-((MAX(Settings!$B$17,Settings!G$11)+Settings!$A$41:$A$64+ABS(MAX(Settings!$B$17,Settings!G$11)-Settings!$A$41:$A$64))/2))+ABS((((MIN(Settings!$C$17,Settings!G$12)+(Settings!$A$41:$A$64+1)-ABS(MIN(Settings!$C$17,Settings!G$12)-(Settings!$A$41:$A$64+1)))/2)-((MAX(Settings!$B$17,Settings!G$11)+Settings!$A$41:$A$64+ABS(MAX(Settings!$B$17,Settings!G$11)-Settings!$A$41:$A$64))/2))))/2),Settings!G$41:G$64) -> 8.97 | H7: =SUMPRODUCT((((((MIN(Settings!$C$17,Settings!H$12)+(Settings!$A$41:$A$64+1)-ABS(MIN(Settings!$C$17,Settings!H$12)-(Settings!$A$41:$A$64+1)))/2)-((MAX(Settings!$B$17,Settings!H$11)+Settings!$A$41:$A$64+ABS(MAX(Settings!$B$17,Settings!H$11)-Settings!$A$41:$A$64))/2))+ABS((((MIN(Settings!$C$17,Settings!H$12)+(Settings!$A$41:$A$64+1)-ABS(MIN(Settings!$C$17,Settings!H$12)-(Settings!$A$41:$A$64+1)))/2)-((MAX(Settings!$B$17,Settings!H$11)+Settings!$A$41:$A$64+ABS(MAX(Settings!$B$17,Settings!H$11)-Settings!$A$41:$A$64))/2))))/2),Settings!H$41:H$64) -> 9.32
A8: =Settings!$A$18 -> 10:00-14:30 | B8: =SUMPRODUCT((((((MIN(Settings!$C$18,Settings!B$12)+(Settings!$A$41:$A$64+1)-ABS(MIN(Settings!$C$18,Settings!B$12)-(Settings!$A$41:$A$64+1)))/2)-((MAX(Settings!$B$18,Settings!B$11)+Settings!$A$41:$A$64+ABS(MAX(Settings!$B$18,Settings!B$11)-Settings!$A$41:$A$64))/2))+ABS((((MIN(Settings!$C$18,Settings!B$12)+(Settings!$A$41:$A$64+1)-ABS(MIN(Settings!$C$18,Settings!B$12)-(Settings!$A$41:$A$64+1)))/2)-((MAX(Settings!$B$18,Settings!B$11)+Settings!$A$41:$A$64+ABS(MAX(Settings!$B$18,Settings!B$11)-Settings!$A$41:$A$64))/2))))/2),Settings!B$41:B$64) -> 3 | C8: =SUMPRODUCT((((((MIN(Settings!$C$18,Settings!C$12)+(Settings!$A$41:$A$64+1)-ABS(MIN(Settings!$C$18,Settings!C$12)-(Settings!$A$41:$A$64+1)))/2)-((MAX(Settings!$B$18,Settings!C$11)+Settings!$A$41:$A$64+ABS(MAX(Settings!$B$18,Settings!C$11)-Settings!$A$41:$A$64))/2))+ABS((((MIN(Settings!$C$18,Settings!C$12)+(Settings!$A$41:$A$64+1)-ABS(MIN(Settings!$C$18,Settings!C$12)-(Settings!$A$41:$A$64+1)))/2)-((MAX(Settings!$B$18,Settings!C$11)+Settings!$A$41:$A$64+ABS(MAX(Settings!$B$18,Settings!C$11)-Settings!$A$41:$A$64))/2))))/2),Settings!C$41:C$64) -> 4.715 | D8: =SUMPRODUCT((((((MIN(Settings!$C$18,Settings!D$12)+(Settings!$A$41:$A$64+1)-ABS(MIN(Settings!$C$18,Settings!D$12)-(Settings!$A$41:$A$64+1)))/2)-((MAX(Settings!$B$18,Settings!D$11)+Settings!$A$41:$A$64+ABS(MAX(Settings!$B$18,Settings!D$11)-Settings!$A$41:$A$64))/2))+ABS((((MIN(Settings!$C$18,Settings!D$12)+(Settings!$A$41:$A$64+1)-ABS(MIN(Settings!$C$18,Settings!D$12)-(Settings!$A$41:$A$64+1)))/2)-((MAX(Settings!$B$18,Settings!D$11)+Settings!$A$41:$A$64+ABS(MAX(Settings!$B$18,Settings!D$11)-Settings!$A$41:$A$64))/2))))/2),Settings!D$41:D$64) -> 4.715 | E8: =SUMPRODUCT((((((MIN(Settings!$C$18,Settings!E$12)+(Settings!$A$41:$A$64+1)-ABS(MIN(Settings!$C$18,Settings!E$12)-(Settings!$A$41:$A$64+1)))/2)-((MAX(Settings!$B$18,Settings!E$11)+Settings!$A$41:$A$64+ABS(MAX(Settings!$B$18,Settings!E$11)-Settings!$A$41:$A$64))/2))+ABS((((MIN(Settings!$C$18,Settings!E$12)+(Settings!$A$41:$A$64+1)-ABS(MIN(Settings!$C$18,Settings!E$12)-(Settings!$A$41:$A$64+1)))/2)-((MAX(Settings!$B$18,Settings!E$11)+Settings!$A$41:$A$64+ABS(MAX(Settings!$B$18,Settings!E$11)-Settings!$A$41:$A$64))/2))))/2),Settings!E$41:E$64) -> 4.715 | F8: =SUMPRODUCT((((((MIN(Settings!$C$18,Settings!F$12)+(Settings!$A$41:$A$64+1)-ABS(MIN(Settings!$C$18,Settings!F$12)-(Settings!$A$41:$A$64+1)))/2)-((MAX(Settings!$B$18,Settings!F$11)+Settings!$A$41:$A$64+ABS(MAX(Settings!$B$18,Settings!F$11)-Settings!$A$41:$A$64))/2))+ABS((((MIN(Settings!$C$18,Settings!F$12)+(Settings!$A$41:$A$64+1)-ABS(MIN(Settings!$C$18,Settings!F$12)-(Settings!$A$41:$A$64+1)))/2)-((MAX(Settings!$B$18,Settings!F$11)+Settings!$A$41:$A$64+ABS(MAX(Settings!$B$18,Settings!F$11)-Settings!$A$41:$A$64))/2))))/2),Settings!F$41:F$64) -> 4.5 | G8: =SUMPRODUCT((((((MIN(Settings!$C$18,Settings!G$12)+(Settings!$A$41:$A$64+1)-ABS(MIN(Settings!$C$18,Settings!G$12)-(Settings!$A$41:$A$64+1)))/2)-((MAX(Settings!$B$18,Settings!G$11)+Settings!$A$41:$A$64+ABS(MAX(Settings!$B$18,Settings!G$11)-Settings!$A$41:$A$64))/2))+ABS((((MIN(Settings!$C$18,Settings!G$12)+(Settings!$A$41:$A$64+1)-ABS(MIN(Settings!$C$18,Settings!G$12)-(Settings!$A$41:$A$64+1)))/2)-((MAX(Settings!$B$18,Settings!G$11)+Settings!$A$41:$A$64+ABS(MAX(Settings!$B$18,Settings!G$11)-Settings!$A$41:$A$64))/2))))/2),Settings!G$41:G$64) -> 4.18 | H8: =SUMPRODUCT((((((MIN(Settings!$C$18,Settings!H$12)+(Settings!$A$41:$A$64+1)-ABS(MIN(Settings!$C$18,Settings!H$12)-(Settings!$A$41:$A$64+1)))/2)-((MAX(Settings!$B$18,Settings!H$11)+Settings!$A$41:$A$64+ABS(MAX(Settings!$B$18,Settings!H$11)-Settings!$A$41:$A$64))/2))+ABS((((MIN(Settings!$C$18,Settings!H$12)+(Settings!$A$41:$A$64+1)-ABS(MIN(Settings!$C$18,Settings!H$12)-(Settings!$A$41:$A$64+1)))/2)-((MAX(Settings!$B$18,Settings!H$11)+Settings!$A$41:$A$64+ABS(MAX(Settings!$B$18,Settings!H$11)-Settings!$A$41:$A$64))/2))))/2),Settings!H$41:H$64) -> 5.01
A9: =Settings!$A$19 -> 10:00-17:00 | B9: =SUMPRODUCT((((((MIN(Settings!$C$19,Settings!B$12)+(Settings!$A$41:$A$64+1)-ABS(MIN(Settings!$C$19,Settings!B$12)-(Settings!$A$41:$A$64+1)))/2)-((MAX(Settings!$B$19,Settings!B$11)+Settings!$A$41:$A$64+ABS(MAX(Settings!$B$19,Settings!B$11)-Settings!$A$41:$A$64))/2))+ABS((((MIN(Settings!$C$19,Settings!B$12)+(Settings!$A$41:$A$64+1)-ABS(MIN(Settings!$C$19,Settings!B$12)-(Settings!$A$41:$A$64+1)))/2)-((MAX(Settings!$B$19,Settings!B$11)+Settings!$A$41:$A$64+ABS(MAX(Settings!$B$19,Settings!B$11)-Settings!$A$41:$A$64))/2))))/2),Settings!B$41:B$64) -> 5.32 | C9: =SUMPRODUCT((((((MIN(Settings!$C$19,Settings!C$12)+(Settings!$A$41:$A$64+1)-ABS(MIN(Settings!$C$19,Settings!C$12)-(Settings!$A$41:$A$64+1)))/2)-((MAX(Settings!$B$19,Settings!C$11)+Settings!$A$41:$A$64+ABS(MAX(Settings!$B$19,Settings!C$11)-Settings!$A$41:$A$64))/2))+ABS((((MIN(Settings!$C$19,Settings!C$12)+(Settings!$A$41:$A$64+1)-ABS(MIN(Settings!$C$19,Settings!C$12)-(Settings!$A$41:$A$64+1)))/2)-((MAX(Settings!$B$19,Settings!C$11)+Settings!$A$41:$A$64+ABS(MAX(Settings!$B$19,Settings!C$11)-Settings!$A$41:$A$64))/2))))/2),Settings!C$41:C$64) -> 7.04 | D9: =SUMPRODUCT((((((MIN(Settings!$C$19,Settings!D$12)+(Settings!$A$41:$A$64+1)-ABS(MIN(Settings!$C$19,Settings!D$12)-(Settings!$A$41:$A$64+1)))/2)-((MAX(Settings!$B$19,Settings!D$11)+Settings!$A$41:$A$64+ABS(MAX(Settings!$B$19,Settings!D$11)-Settings!$A$41:$A$64))/2))+ABS((((MIN(Settings!$C$19,Settings!D$12)+(Settings!$A$41:$A$64+1)-ABS(MIN(Settings!$C$19,Settings!D$12)-(Settings!$A$41:$A$64+1)))/2)-((MAX(Settings!$B$19,Settings!D$11)+Settings!$A$41:$A$64+ABS(MAX(Settings!$B$19,Settings!D$11)-Settings!$A$41:$A$64))/2))))/2),Settings!D$41:D$64) -> 7.04 | E9: =SUMPRODUCT((((((MIN(Settings!$C$19,Settings!E$12)+(Settings!$A$41:$A$64+1)-ABS(MIN(Settings!$C$19,Settings!E$12)-(Settings!$A$41:$A$64+1)))/2)-((MAX(Settings!$B$19,Settings!E$11)+Settings!$A$41:$A$64+ABS(MAX(Settings!$B$19,Settings!E$11)-Settings!$A$41:$A$64))/2))+ABS((((MIN(Settings!$C$19,Settings!E$12)+(Settings!$A$41:$A$64+1)-ABS(MIN(Settings!$C$19,Settings!E$12)-(Settings!$A$41:$A$64+1)))/2)-((MAX(Settings!$B$19,Settings!E$11)+Settings!$A$41:$A$64+ABS(MAX(Settings!$B$19,Settings!E$11)-Settings!$A$41:$A$64))/2))))/2),Settings!E$41:E$64) -> 7.04 | F9: =SUMPRODUCT((((((MIN(Settings!$C$19,Settings!F$12)+(Settings!$A$41:$A$64+1)-ABS(MIN(Settings!$C$19,Settings!F$12)-(Settings!$A$41:$A$64+1)))/2)-((MAX(Settings!$B$19,Settings!F$11)+Settings!$A$41:$A$64+ABS(MAX(Settings!$B$19,Settings!F$11)-Settings!$A$41:$A$64))/2))+ABS((((MIN(Settings!$C$19,Settings!F$12)+(Settings!$A$41:$A$64+1)-ABS(MIN(Settings!$C$19,Settings!F$12)-(Settings!$A$41:$A$64+1)))/2)-((MAX(Settings!$B$19,Settings!F$11)+Settings!$A$41:$A$64+ABS(MAX(Settings!$B$19,Settings!F$11)-Settings!$A$41:$A$64))/2))))/2),Settings!F$41:F$64) -> 6.84 | G9: =SUMPRODUCT((((((MIN(Settings!$C$19,Settings!G$12)+(Settings!$A$41:$A$64+1)-ABS(MIN(Settings!$C$19,Settings!G$12)-(Settings!$A$41:$A$64+1)))/2)-((MAX(Settings!$B$19,Settings!G$11)+Settings!$A$41:$A$64+ABS(MAX(Settings!$B$19,Settings!G$11)-Settings!$A$41:$A$64))/2))+ABS((((MIN(Settings!$C$19,Settings!G$12)+(Settings!$A$41:$A$64+1)-ABS(MIN(Settings!$C$19,Settings!G$12)-(Settings!$A$41:$A$64+1)))/2)-((MAX(Settings!$B$19,Settings!G$11)+Settings!$A$41:$A$64+ABS(MAX(Settings!$B$19,Settings!G$11)-Settings!$A$41:$A$64))/2))))/2),Settings!G$41:G$64) -> 6.53 | H9: =SUMPRODUCT((((((MIN(Settings!$C$19,Settings!H$12)+(Settings!$A$41:$A$64+1)-ABS(MIN(Settings!$C$19,Settings!H$12)-(Settings!$A$41:$A$64+1)))/2)-((MAX(Settings!$B$19,Settings!H$11)+Settings!$A$41:$A$64+ABS(MAX(Settings!$B$19,Settings!H$11)-Settings!$A$41:$A$64))/2))+ABS((((MIN(Settings!$C$19,Settings!H$12)+(Settings!$A$41:$A$64+1)-ABS(MIN(Settings!$C$19,Settings!H$12)-(Settings!$A$41:$A$64+1)))/2)-((MAX(Settings!$B$19,Settings!H$11)+Settings!$A$41:$A$64+ABS(MAX(Settings!$B$19,Settings!H$11)-Settings!$A$41:$A$64))/2))))/2),Settings!H$41:H$64) -> 7.56
A10: =Settings!$A$20 -> 12:30-19:00 | B10: =SUMPRODUCT((((((MIN(Settings!$C$20,Settings!B$12)+(Settings!$A$41:$A$64+1)-ABS(MIN(Settings!$C$20,Settings!B$12)-(Settings!$A$41:$A$64+1)))/2)-((MAX(Settings!$B$20,Settings!B$11)+Settings!$A$41:$A$64+ABS(MAX(Settings!$B$20,Settings!B$11)-Settings!$A$41:$A$64))/2))+ABS((((MIN(Settings!$C$20,Settings!B$12)+(Settings!$A$41:$A$64+1)-ABS(MIN(Settings!$C$20,Settings!B$12)-(Settings!$A$41:$A$64+1)))/2)-((MAX(Settings!$B$20,Settings!B$11)+Settings!$A$41:$A$64+ABS(MAX(Settings!$B$20,Settings!B$11)-Settings!$A$41:$A$64))/2))))/2),Settings!B$41:B$64) -> 5.37 | C10: =SUMPRODUCT((((((MIN(Settings!$C$20,Settings!C$12)+(Settings!$A$41:$A$64+1)-ABS(MIN(Settings!$C$20,Settings!C$12)-(Settings!$A$41:$A$64+1)))/2)-((MAX(Settings!$B$20,Settings!C$11)+Settings!$A$41:$A$64+ABS(MAX(Settings!$B$20,Settings!C$11)-Settings!$A$41:$A$64))/2))+ABS((((MIN(Settings!$C$20,Settings!C$12)+(Settings!$A$41:$A$64+1)-ABS(MIN(Settings!$C$20,Settings!C$12)-(Settings!$A$41:$A$64+1)))/2)-((MAX(Settings!$B$20,Settings!C$11)+Settings!$A$41:$A$64+ABS(MAX(Settings!$B$20,Settings!C$11)-Settings!$A$41:$A$64))/2))))/2),Settings!C$41:C$64) -> 6.845 | D10: =SUMPRODUCT((((((MIN(Settings!$C$20,Settings!D$12)+(Settings!$A$41:$A$64+1)-ABS(MIN(Settings!$C$20,Settings!D$12)-(Settings!$A$41:$A$64+1)))/2)-((MAX(Settings!$B$20,Settings!D$11)+Settings!$A$41:$A$64+ABS(MAX(Settings!$B$20,Settings!D$11)-Settings!$A$41:$A$64))/2))+ABS((((MIN(Settings!$C$20,Settings!D$12)+(Settings!$A$41:$A$64+1)-ABS(MIN(Settings!$C$20,Settings!D$12)-(Settings!$A$41:$A$64+1)))/2)-((MAX(Settings!$B$20,Settings!D$11)+Settings!$A$41:$A$64+ABS(MAX(Settings!$B$20,Settings!D$11)-Settings!$A$41:$A$64))/2))))/2),Settings!D$41:D$64) -> 6.845 | E10: =SUMPRODUCT((((((MIN(Settings!$C$20,Settings!E$12)+(Settings!$A$41:$A$64+1)-ABS(MIN(Settings!$C$20,Settings!E$12)-(Settings!$A$41:$A$64+1)))/2)-((MAX(Settings!$B$20,Settings!E$11)+Settings!$A$41:$A$64+ABS(MAX(Settings!$B$20,Settings!E$11)-Settings!$A$41:$A$64))/2))+ABS((((MIN(Settings!$C$20,Settings!E$12)+(Settings!$A$41:$A$64+1)-ABS(MIN(Settings!$C$20,Settings!E$12)-(Settings!$A$41:$A$64+1)))/2)-((MAX(Settings!$B$20,Settings!E$11)+Settings!$A$41:$A$64+ABS(MAX(Settings!$B$20,Settings!E$11)-Settings!$A$41:$A$64))/2))))/2),Settings!E$41:E$64) -> 6.845 | F10: =SUMPRODUCT((((((MIN(Settings!$C$20,Settings!F$12)+(Settings!$A$41:$A$64+1)-ABS(MIN(Settings!$C$20,Settings!F$12)-(Settings!$A$41:$A$64+1)))/2)-((MAX(Settings!$B$20,Settings!F$11)+Settings!$A$41:$A$64+ABS(MAX(Settings!$B$20,Settings!F$11)-Settings!$A$41:$A$64))/2))+ABS((((MIN(Settings!$C$20,Settings!F$12)+(Settings!$A$41:$A$64+1)-ABS(MIN(Settings!$C$20,Settings!F$12)-(Settings!$A$41:$A$64+1)))/2)-((MAX(Settings!$B$20,Settings!F$11)+Settings!$A$41:$A$64+ABS(MAX(Settings!$B$20,Settings!F$11)-Settings!$A$41:$A$64))/2))))/2),Settings!F$41:F$64) -> 6.855 | G10: =SUMPRODUCT((((((MIN(Settings!$C$20,Settings!G$12)+(Settings!$A$41:$A$64+1)-ABS(MIN(Settings!$C$20,Settings!G$12)-(Settings!$A$41:$A$64+1)))/2)-((MAX(Settings!$B$20,Settings!G$11)+Settings!$A$41:$A$64+ABS(MAX(Settings!$B$20,Settings!G$11)-Settings!$A$41:$A$64))/2))+ABS((((MIN(Settings!$C$20,Settings!G$12)+(Settings!$A$41:$A$64+1)-ABS(MIN(Settings!$C$20,Settings!G$12)-(Settings!$A$41:$A$64+1)))/2)-((MAX(Settings!$B$20,Settings!G$11)+Settings!$A$41:$A$64+ABS(MAX(Settings!$B$20,Settings!G$11)-Settings!$A$41:$A$64))/2))))/2),Settings!G$41:G$64) -> 6.855 | H10: =SUMPRODUCT((((((MIN(Settings!$C$20,Settings!H$12)+(Settings!$A$41:$A$64+1)-ABS(MIN(Settings!$C$20,Settings!H$12)-(Settings!$A$41:$A$64+1)))/2)-((MAX(Settings!$B$20,Settings!H$11)+Settings!$A$41:$A$64+ABS(MAX(Settings!$B$20,Settings!H$11)-Settings!$A$41:$A$64))/2))+ABS((((MIN(Settings!$C$20,Settings!H$12)+(Settings!$A$41:$A$64+1)-ABS(MIN(Settings!$C$20,Settings!H$12)-(Settings!$A$41:$A$64+1)))/2)-((MAX(Settings!$B$20,Settings!H$11)+Settings!$A$41:$A$64+ABS(MAX(Settings!$B$20,Settings!H$11)-Settings!$A$41:$A$64))/2))))/2),Settings!H$41:H$64) -> 6.57
A11: =Settings!$A$21 -> 11:30-20:30 | B11: =SUMPRODUCT((((((MIN(Settings!$C$21,Settings!B$12)+(Settings!$A$41:$A$64+1)-ABS(MIN(Settings!$C$21,Settings!B$12)-(Settings!$A$41:$A$64+1)))/2)-((MAX(Settings!$B$21,Settings!B$11)+Settings!$A$41:$A$64+ABS(MAX(Settings!$B$21,Settings!B$11)-Settings!$A$41:$A$64))/2))+ABS((((MIN(Settings!$C$21,Settings!B$12)+(Settings!$A$41:$A$64+1)-ABS(MIN(Settings!$C$21,Settings!B$12)-(Settings!$A$41:$A$64+1)))/2)-((MAX(Settings!$B$21,Settings!B$11)+Settings!$A$41:$A$64+ABS(MAX(Settings!$B$21,Settings!B$11)-Settings!$A$41:$A$64))/2))))/2),Settings!B$41:B$64) -> 6 | C11: =SUMPRODUCT((((((MIN(Settings!$C$21,Settings!C$12)+(Settings!$A$41:$A$64+1)-ABS(MIN(Settings!$C$21,Settings!C$12)-(Settings!$A$41:$A$64+1)))/2)-((MAX(Settings!$B$21,Settings!C$11)+Settings!$A$41:$A$64+ABS(MAX(Settings!$B$21,Settings!C$11)-Settings!$A$41:$A$64))/2))+ABS((((MIN(Settings!$C$21,Settings!C$12)+(Settings!$A$41:$A$64+1)-ABS(MIN(Settings!$C$21,Settings!C$12)-(Settings!$A$41:$A$64+1)))/2)-((MAX(Settings!$B$21,Settings!C$11)+Settings!$A$41:$A$64+ABS(MAX(Settings!$B$21,Settings!C$11)-Settings!$A$41:$A$64))/2))))/2),Settings!C$41:C$64) -> 8.72 | D11: =SUMPRODUCT((((((MIN(Settings!$C$21,Settings!D$12)+(Settings!$A$41:$A$64+1)-ABS(MIN(Settings!$C$21,Settings!D$12)-(Settings!$A$41:$A$64+1)))/2)-((MAX(Settings!$B$21,Settings!D$11)+Settings!$A$41:$A$64+ABS(MAX(Settings!$B$21,Settings!D$11)-Settings!$A$41:$A$64))/2))+ABS((((MIN(Settings!$C$21,Settings!D$12)+(Settings!$A$41:$A$64+1)-ABS(MIN(Settings!$C$21,Settings!D$12)-(Settings!$A$41:$A$64+1)))/2)-((MAX(Settings!$B$21,Settings!D$11)+Settings!$A$41:$A$64+ABS(MAX(Settings!$B$21,Settings!D$11)-Settings!$A$41:$A$64))/2))))/2),Settings!D$41:D$64) -> 8.72 | E11: =SUMPRODUCT((((((MIN(Settings!$C$21,Settings!E$12)+(Settings!$A$41:$A$64+1)-ABS(MIN(Settings!$C$21,Settings!E$12)-(Settings!$A$41:$A$64+1)))/2)-((MAX(Settings!$B$21,Settings!E$11)+Settings!$A$41:$A$64+ABS(MAX(Settings!$B$21,Settings!E$11)-Settings!$A$41:$A$64))/2))+ABS((((MIN(Settings!$C$21,Settings!E$12)+(Settings!$A$41:$A$64+1)-ABS(MIN(Settings!$C$21,Settings!E$12)-(Settings!$A$41:$A$64+1)))/2)-((MAX(Settings!$B$21,Settings!E$11)+Settings!$A$41:$A$64+ABS(MAX(Settings!$B$21,Settings!E$11)-Settings!$A$41:$A$64))/2))))/2),Settings!E$41:E$64) -> 8.72 | F11: =SUMPRODUCT((((((MIN(Settings!$C$21,Settings!F$12)+(Settings!$A$41:$A$64+1)-ABS(MIN(Settings!$C$21,Settings!F$12)-(Settings!$A$41:$A$64+1)))/2)-((MAX(Settings!$B$21,Settings!F$11)+Settings!$A$41:$A$64+ABS(MAX(Settings!$B$21,Settings!F$11)-Settings!$A$41:$A$64))/2))+ABS((((MIN(Settings!$C$21,Settings!F$12)+(Settings!$A$41:$A$64+1)-ABS(MIN(Settings!$C$21,Settings!F$12)-(Settings!$A$41:$A$64+1)))/2)-((MAX(Settings!$B$21,Settings!F$11)+Settings!$A$41:$A$64+ABS(MAX(Settings!$B$21,Settings!F$11)-Settings!$A$41:$A$64))/2))))/2),Settings!F$41:F$64) -> 8.765 | G11: =SUMPRODUCT((((((MIN(Settings!$C$21,Settings!G$12)+(Settings!$A$41:$A$64+1)-ABS(MIN(Settings!$C$21,Settings!G$12)-(Settings!$A$41:$A$64+1)))/2)-((MAX(Settings!$B$21,Settings!G$11)+Settings!$A$41:$A$64+ABS(MAX(Settings!$B$21,Settings!G$11)-Settings!$A$41:$A$64))/2))+ABS((((MIN(Settings!$C$21,Settings!G$12)+(Settings!$A$41:$A$64+1)-ABS(MIN(Settings!$C$21,Settings!G$12)-(Settings!$A$41:$A$64+1)))/2)-((MAX(Settings!$B$21,Settings!G$11)+Settings!$A$41:$A$64+ABS(MAX(Settings!$B$21,Settings!G$11)-Settings!$A$41:$A$64))/2))))/2),Settings!G$41:G$64) -> 8.825 | H11: =SUMPRODUCT((((((MIN(Settings!$C$21,Settings!H$12)+(Settings!$A$41:$A$64+1)-ABS(MIN(Settings!$C$21,Settings!H$12)-(Settings!$A$41:$A$64+1)))/2)-((MAX(Settings!$B$21,Settings!H$11)+Settings!$A$41:$A$64+ABS(MAX(Settings!$B$21,Settings!H$11)-Settings!$A$41:$A$64))/2))+ABS((((MIN(Settings!$C$21,Settings!H$12)+(Settings!$A$41:$A$64+1)-ABS(MIN(Settings!$C$21,Settings!H$12)-(Settings!$A$41:$A$64+1)))/2)-((MAX(Settings!$B$21,Settings!H$11)+Settings!$A$41:$A$64+ABS(MAX(Settings!$B$21,Settings!H$11)-Settings!$A$41:$A$64))/2))))/2),Settings!H$41:H$64) -> 8.415
A12: =Settings!$A$22 -> 13:30-20:30 | B12: =SUMPRODUCT((((((MIN(Settings!$C$22,Settings!B$12)+(Settings!$A$41:$A$64+1)-ABS(MIN(Settings!$C$22,Settings!B$12)-(Settings!$A$41:$A$64+1)))/2)-((MAX(Settings!$B$22,Settings!B$11)+Settings!$A$41:$A$64+ABS(MAX(Settings!$B$22,Settings!B$11)-Settings!$A$41:$A$64))/2))+ABS((((MIN(Settings!$C$22,Settings!B$12)+(Settings!$A$41:$A$64+1)-ABS(MIN(Settings!$C$22,Settings!B$12)-(Settings!$A$41:$A$64+1)))/2)-((MAX(Settings!$B$22,Settings!B$11)+Settings!$A$41:$A$64+ABS(MAX(Settings!$B$22,Settings!B$11)-Settings!$A$41:$A$64))/2))))/2),Settings!B$41:B$64) -> 4.135 | C12: =SUMPRODUCT((((((MIN(Settings!$C$22,Settings!C$12)+(Settings!$A$41:$A$64+1)-ABS(MIN(Settings!$C$22,Settings!C$12)-(Settings!$A$41:$A$64+1)))/2)-((MAX(Settings!$B$22,Settings!C$11)+Settings!$A$41:$A$64+ABS(MAX(Settings!$B$22,Settings!C$11)-Settings!$A$41:$A$64))/2))+ABS((((MIN(Settings!$C$22,Settings!C$12)+(Settings!$A$41:$A$64+1)-ABS(MIN(Settings!$C$22,Settings!C$12)-(Settings!$A$41:$A$64+1)))/2)-((MAX(Settings!$B$22,Settings!C$11)+Settings!$A$41:$A$64+ABS(MAX(Settings!$B$22,Settings!C$11)-Settings!$A$41:$A$64))/2))))/2),Settings!C$41:C$64) -> 6.46 | D12: =SUMPRODUCT((((((MIN(Settings!$C$22,Settings!D$12)+(Settings!$A$41:$A$64+1)-ABS(MIN(Settings!$C$22,Settings!D$12)-(Settings!$A$41:$A$64+1)))/2)-((MAX(Settings!$B$22,Settings!D$11)+Settings!$A$41:$A$64+ABS(MAX(Settings!$B$22,Settings!D$11)-Settings!$A$41:$A$64))/2))+ABS((((MIN(Settings!$C$22,Settings!D$12)+(Settings!$A$41:$A$64+1)-ABS(MIN(Settings!$C$22,Settings!D$12)-(Settings!$A$41:$A$64+1)))/2)-((MAX(Settings!$B$22,Settings!D$11)+Settings!$A$41:$A$64+ABS(MAX(Settings!$B$22,Settings!D$11)-Settings!$A$41:$A$64))/2))))/2),Settings!D$41:D$64) -> 6.46 | E12: =SUMPRODUCT((((((MIN(Settings!$C$22,Settings!E$12)+(Settings!$A$41:$A$64+1)-ABS(MIN(Settings!$C$22,Settings!E$12)-(Settings!$A$41:$A$64+1)))/2)-((MAX(Settings!$B$22,Settings!E$11)+Settings!$A$41:$A$64+ABS(MAX(Settings!$B$22,Settings!E$11)-Settings!$A$41:$A$64))/2))+ABS((((MIN(Settings!$C$22,Settings!E$12)+(Settings!$A$41:$A$64+1)-ABS(MIN(Settings!$C$22,Settings!E$12)-(Settings!$A$41:$A$64+1)))/2)-((MAX(Settings!$B$22,Settings!E$11)+Settings!$A$41:$A$64+ABS(MAX(Settings!$B$22,Settings!E$11)-Settings!$A$41:$A$64))/2))))/2),Settings!E$41:E$64) -> 6.46 | F12: =SUMPRODUCT((((((MIN(Settings!$C$22,Settings!F$12)+(Settings!$A$41:$A$64+1)-ABS(MIN(Settings!$C$22,Settings!F$12)-(Settings!$A$41:$A$64+1)))/2)-((MAX(Settings!$B$22,Settings!F$11)+Settings!$A$41:$A$64+ABS(MAX(Settings!$B$22,Settings!F$11)-Settings!$A$41:$A$64))/2))+ABS((((MIN(Settings!$C$22,Settings!F$12)+(Settings!$A$41:$A$64+1)-ABS(MIN(Settings!$C$22,Settings!F$12)-(Settings!$A$41:$A$64+1)))/2)-((MAX(Settings!$B$22,Settings!F$11)+Settings!$A$41:$A$64+ABS(MAX(Settings!$B$22,Settings!F$11)-Settings!$A$41:$A$64))/2))))/2),Settings!F$41:F$64) -> 6.615 | G12: =SUMPRODUCT((((((MIN(Settings!$C$22,Settings!G$12)+(Settings!$A$41:$A$64+1)-ABS(MIN(Settings!$C$22,Settings!G$12)-(Settings!$A$41:$A$64+1)))/2)-((MAX(Settings!$B$22,Settings!G$11)+Settings!$A$41:$A$64+ABS(MAX(Settings!$B$22,Settings!G$11)-Settings!$A$41:$A$64))/2))+ABS((((MIN(Settings!$C$22,Settings!G$12)+(Settings!$A$41:$A$64+1)-ABS(MIN(Settings!$C$22,Settings!G$12)-(Settings!$A$41:$A$64+1)))/2)-((MAX(Settings!$B$22,Settings!G$11)+Settings!$A$41:$A$64+ABS(MAX(Settings!$B$22,Settings!G$11)-Settings!$A$41:$A$64))/2))))/2),Settings!G$41:G$64) -> 6.83 | H12: =SUMPRODUCT((((((MIN(Settings!$C$22,Settings!H$12)+(Settings!$A$41:$A$64+1)-ABS(MIN(Settings!$C$22,Settings!H$12)-(Settings!$A$41:$A$64+1)))/2)-((MAX(Settings!$B$22,Settings!H$11)+Settings!$A$41:$A$64+ABS(MAX(Settings!$B$22,Settings!H$11)-Settings!$A$41:$A$64))/2))+ABS((((MIN(Settings!$C$22,Settings!H$12)+(Settings!$A$41:$A$64+1)-ABS(MIN(Settings!$C$22,Settings!H$12)-(Settings!$A$41:$A$64+1)))/2)-((MAX(Settings!$B$22,Settings!H$11)+Settings!$A$41:$A$64+ABS(MAX(Settings!$B$22,Settings!H$11)-Settings!$A$41:$A$64))/2))))/2),Settings!H$41:H$64) -> 6.105
A14: B. Shift value = A x (1 - lunch fraction) / standard length
A15: Shift | B15: Sun | C15: Mon | D15: Tue | E15: Wed | F15: Thu | G15: Fri | H15: Sat
A16: =Settings!$A$16 -> 8:00-17:00 | B16: =B6*(1-Settings!$F$16)/Settings!$B$33 -> 0.59111111 | C16: =C6*(1-Settings!$F$16)/Settings!$B$33 -> 0.78222222 | D16: =D6*(1-Settings!$F$16)/Settings!$B$33 -> 0.78222222 | E16: =E6*(1-Settings!$F$16)/Settings!$B$33 -> 0.78222222 | F16: =F6*(1-Settings!$F$16)/Settings!$B$33 -> 0.76 | G16: =G6*(1-Settings!$F$16)/Settings!$B$33 -> 0.72555556 | H16: =H6*(1-Settings!$F$16)/Settings!$B$33 -> 0.84
A17: =Settings!$A$17 -> 10:00-19:00 | B17: =B7*(1-Settings!$F$17)/Settings!$B$33 -> 0.66666667 | C17: =C7*(1-Settings!$F$17)/Settings!$B$33 -> 1.02 | D17: =D7*(1-Settings!$F$17)/Settings!$B$33 -> 1.02 | E17: =E7*(1-Settings!$F$17)/Settings!$B$33 -> 1.02 | F17: =F7*(1-Settings!$F$17)/Settings!$B$33 -> 1.0111111 | G17: =G7*(1-Settings!$F$17)/Settings!$B$33 -> 0.99666667 | H17: =H7*(1-Settings!$F$17)/Settings!$B$33 -> 1.0355556
A18: =Settings!$A$18 -> 10:00-14:30 | B18: =B8*(1-Settings!$F$18)/Settings!$B$33 -> 0.33333333 | C18: =C8*(1-Settings!$F$18)/Settings!$B$33 -> 0.52388889 | D18: =D8*(1-Settings!$F$18)/Settings!$B$33 -> 0.52388889 | E18: =E8*(1-Settings!$F$18)/Settings!$B$33 -> 0.52388889 | F18: =F8*(1-Settings!$F$18)/Settings!$B$33 -> 0.5 | G18: =G8*(1-Settings!$F$18)/Settings!$B$33 -> 0.46444444 | H18: =H8*(1-Settings!$F$18)/Settings!$B$33 -> 0.55666667
A19: =Settings!$A$19 -> 10:00-17:00 | B19: =B9*(1-Settings!$F$19)/Settings!$B$33 -> 0.6175 | C19: =C9*(1-Settings!$F$19)/Settings!$B$33 -> 0.81714286 | D19: =D9*(1-Settings!$F$19)/Settings!$B$33 -> 0.81714286 | E19: =E9*(1-Settings!$F$19)/Settings!$B$33 -> 0.81714286 | F19: =F9*(1-Settings!$F$19)/Settings!$B$33 -> 0.79392857 | G19: =G9*(1-Settings!$F$19)/Settings!$B$33 -> 0.75794643 | H19: =H9*(1-Settings!$F$19)/Settings!$B$33 -> 0.8775
A20: =Settings!$A$20 -> 12:30-19:00 | B20: =B10*(1-Settings!$F$20)/Settings!$B$33 -> 0.61961538 | C20: =C10*(1-Settings!$F$20)/Settings!$B$33 -> 0.78980769 | D20: =D10*(1-Settings!$F$20)/Settings!$B$33 -> 0.78980769 | E20: =E10*(1-Settings!$F$20)/Settings!$B$33 -> 0.78980769 | F20: =F10*(1-Settings!$F$20)/Settings!$B$33 -> 0.79096154 | G20: =G10*(1-Settings!$F$20)/Settings!$B$33 -> 0.79096154 | H20: =H10*(1-Settings!$F$20)/Settings!$B$33 -> 0.75807692
A21: =Settings!$A$21 -> 11:30-20:30 | B21: =B11*(1-Settings!$F$21)/Settings!$B$33 -> 0.66666667 | C21: =C11*(1-Settings!$F$21)/Settings!$B$33 -> 0.96888889 | D21: =D11*(1-Settings!$F$21)/Settings!$B$33 -> 0.96888889 | E21: =E11*(1-Settings!$F$21)/Settings!$B$33 -> 0.96888889 | F21: =F11*(1-Settings!$F$21)/Settings!$B$33 -> 0.97388889 | G21: =G11*(1-Settings!$F$21)/Settings!$B$33 -> 0.98055556 | H21: =H11*(1-Settings!$F$21)/Settings!$B$33 -> 0.935
A22: =Settings!$A$22 -> 13:30-20:30 | B22: =B12*(1-Settings!$F$22)/Settings!$B$33 -> 0.47995536 | C22: =C12*(1-Settings!$F$22)/Settings!$B$33 -> 0.74982143 | D22: =D12*(1-Settings!$F$22)/Settings!$B$33 -> 0.74982143 | E22: =E12*(1-Settings!$F$22)/Settings!$B$33 -> 0.74982143 | F22: =F12*(1-Settings!$F$22)/Settings!$B$33 -> 0.7678125 | G22: =G12*(1-Settings!$F$22)/Settings!$B$33 -> 0.79276786 | H22: =H12*(1-Settings!$F$22)/Settings!$B$33 -> 0.70861607
